[2023-03-19T20:57:16.032+0000] {taskinstance.py:1084} INFO - Dependencies all met for dep_context=non-requeueable deps ti=<TaskInstance: project_spark_processing.process_data scheduled__2023-03-18T00:00:00+00:00 [queued]>
[2023-03-19T20:57:16.045+0000] {taskinstance.py:1084} INFO - Dependencies all met for dep_context=requeueable deps ti=<TaskInstance: project_spark_processing.process_data scheduled__2023-03-18T00:00:00+00:00 [queued]>
[2023-03-19T20:57:16.045+0000] {taskinstance.py:1282} INFO - 
--------------------------------------------------------------------------------
[2023-03-19T20:57:16.045+0000] {taskinstance.py:1283} INFO - Starting attempt 4 of 4
[2023-03-19T20:57:16.046+0000] {taskinstance.py:1284} INFO - 
--------------------------------------------------------------------------------
[2023-03-19T20:57:16.067+0000] {taskinstance.py:1303} INFO - Executing <Task(DataprocSubmitJobOperator): process_data> on 2023-03-18 00:00:00+00:00
[2023-03-19T20:57:16.076+0000] {standard_task_runner.py:55} INFO - Started process 17188 to run task
[2023-03-19T20:57:16.082+0000] {standard_task_runner.py:82} INFO - Running: ['***', 'tasks', 'run', 'project_spark_processing', 'process_data', 'scheduled__2023-03-18T00:00:00+00:00', '--job-id', '148', '--raw', '--subdir', 'DAGS_FOLDER/p_submit_job_draft.py', '--cfg-path', '/tmp/tmp008yx1a0']
[2023-03-19T20:57:16.086+0000] {standard_task_runner.py:83} INFO - Job 148: Subtask process_data
[2023-03-19T20:57:16.107+0000] {warnings.py:110} WARNING - /home/***/.local/lib/python3.7/site-packages/***/settings.py:250: DeprecationWarning: The sql_alchemy_conn option in [core] has been moved to the sql_alchemy_conn option in [database] - the old setting has been used, but please update your config.
  SQL_ALCHEMY_CONN = conf.get("database", "SQL_ALCHEMY_CONN")

[2023-03-19T20:57:16.139+0000] {warnings.py:110} WARNING - /home/***/.local/lib/python3.7/site-packages/***/utils/sqlalchemy.py:124: DeprecationWarning: The sql_alchemy_conn option in [core] has been moved to the sql_alchemy_conn option in [database] - the old setting has been used, but please update your config.
  return not conf.get("database", "sql_alchemy_conn").startswith("mssql")

[2023-03-19T20:57:16.181+0000] {task_command.py:388} INFO - Running <TaskInstance: project_spark_processing.process_data scheduled__2023-03-18T00:00:00+00:00 [running]> on host 50ce40c43c89
[2023-03-19T20:57:16.286+0000] {taskinstance.py:1511} INFO - Exporting the following env vars:
AIRFLOW_CTX_DAG_OWNER=***
AIRFLOW_CTX_DAG_ID=project_spark_processing
AIRFLOW_CTX_TASK_ID=process_data
AIRFLOW_CTX_EXECUTION_DATE=2023-03-18T00:00:00+00:00
AIRFLOW_CTX_TRY_NUMBER=4
AIRFLOW_CTX_DAG_RUN_ID=scheduled__2023-03-18T00:00:00+00:00
[2023-03-19T20:57:16.287+0000] {dataproc.py:1985} INFO - Submitting job
[2023-03-19T20:57:16.289+0000] {crypto.py:83} WARNING - empty cryptography key - values will not be stored encrypted.
[2023-03-19T20:57:16.290+0000] {base.py:73} INFO - Using connection ID 'google_cloud_default' for task execution.
[2023-03-19T20:57:16.491+0000] {taskinstance.py:1775} ERROR - Task failed with exception
Traceback (most recent call last):
  File "/home/airflow/.local/lib/python3.7/site-packages/google/api_core/grpc_helpers.py", line 50, in error_remapped_callable
    return callable_(*args, **kwargs)
  File "/home/airflow/.local/lib/python3.7/site-packages/grpc/_channel.py", line 946, in __call__
    return _end_unary_response_blocking(state, call, False, None)
  File "/home/airflow/.local/lib/python3.7/site-packages/grpc/_channel.py", line 849, in _end_unary_response_blocking
    raise _InactiveRpcError(state)
grpc._channel._InactiveRpcError: <_InactiveRpcError of RPC that terminated with:
	status = StatusCode.ALREADY_EXISTS
	details = "Already exists: Failed to submit job: Job projects/dtc-de-course-375420/regions/europe-west6/jobs/your_job_id"
	debug_error_string = "UNKNOWN:Error received from peer ipv4:216.58.215.234:443 {grpc_message:"Already exists: Failed to submit job: Job projects/dtc-de-course-375420/regions/europe-west6/jobs/your_job_id", grpc_status:6, created_time:"2023-03-19T20:57:16.490840322+00:00"}"
>

The above exception was the direct cause of the following exception:

Traceback (most recent call last):
  File "/home/airflow/.local/lib/python3.7/site-packages/airflow/providers/google/cloud/operators/dataproc.py", line 1994, in execute
    metadata=self.metadata,
  File "/home/airflow/.local/lib/python3.7/site-packages/airflow/providers/google/common/hooks/base_google.py", line 468, in inner_wrapper
    return func(self, *args, **kwargs)
  File "/home/airflow/.local/lib/python3.7/site-packages/airflow/providers/google/cloud/hooks/dataproc.py", line 794, in submit_job
    metadata=metadata,
  File "/home/airflow/.local/lib/python3.7/site-packages/google/cloud/dataproc_v1/services/job_controller/client.py", line 524, in submit_job
    metadata=metadata,
  File "/home/airflow/.local/lib/python3.7/site-packages/google/api_core/gapic_v1/method.py", line 154, in __call__
    return wrapped_func(*args, **kwargs)
  File "/home/airflow/.local/lib/python3.7/site-packages/google/api_core/retry.py", line 288, in retry_wrapped_func
    on_error=on_error,
  File "/home/airflow/.local/lib/python3.7/site-packages/google/api_core/retry.py", line 190, in retry_target
    return target()
  File "/home/airflow/.local/lib/python3.7/site-packages/google/api_core/grpc_helpers.py", line 52, in error_remapped_callable
    raise exceptions.from_grpc_error(exc) from exc
google.api_core.exceptions.AlreadyExists: 409 Already exists: Failed to submit job: Job projects/dtc-de-course-375420/regions/europe-west6/jobs/your_job_id
[2023-03-19T20:57:16.507+0000] {taskinstance.py:1326} INFO - Marking task as FAILED. dag_id=project_spark_processing, task_id=process_data, execution_date=20230318T000000, start_date=20230319T205716, end_date=20230319T205716
[2023-03-19T20:57:16.522+0000] {standard_task_runner.py:105} ERROR - Failed to execute job 148 for task process_data (409 Already exists: Failed to submit job: Job projects/dtc-de-course-375420/regions/europe-west6/jobs/your_job_id; 17188)
[2023-03-19T20:57:16.537+0000] {local_task_job.py:212} INFO - Task exited with return code 1
[2023-03-19T20:57:16.574+0000] {taskinstance.py:2585} INFO - 0 downstream tasks scheduled from follow-on schedule check
