[2023-03-19T21:11:55.788+0000] {taskinstance.py:1084} INFO - Dependencies all met for dep_context=non-requeueable deps ti=<TaskInstance: project_spark_processing.process_data scheduled__2023-03-18T00:00:00+00:00 [queued]>
[2023-03-19T21:11:55.830+0000] {taskinstance.py:1084} INFO - Dependencies all met for dep_context=requeueable deps ti=<TaskInstance: project_spark_processing.process_data scheduled__2023-03-18T00:00:00+00:00 [queued]>
[2023-03-19T21:11:55.831+0000] {taskinstance.py:1282} INFO - 
--------------------------------------------------------------------------------
[2023-03-19T21:11:55.832+0000] {taskinstance.py:1283} INFO - Starting attempt 6 of 7
[2023-03-19T21:11:55.832+0000] {taskinstance.py:1284} INFO - 
--------------------------------------------------------------------------------
[2023-03-19T21:11:55.890+0000] {taskinstance.py:1303} INFO - Executing <Task(DataprocSubmitJobOperator): process_data> on 2023-03-18 00:00:00+00:00
[2023-03-19T21:11:55.900+0000] {standard_task_runner.py:55} INFO - Started process 18089 to run task
[2023-03-19T21:11:55.915+0000] {standard_task_runner.py:82} INFO - Running: ['***', 'tasks', 'run', 'project_spark_processing', 'process_data', 'scheduled__2023-03-18T00:00:00+00:00', '--job-id', '150', '--raw', '--subdir', 'DAGS_FOLDER/p_submit_job_draft.py', '--cfg-path', '/tmp/tmpps6fwn3t']
[2023-03-19T21:11:55.931+0000] {standard_task_runner.py:83} INFO - Job 150: Subtask process_data
[2023-03-19T21:11:55.986+0000] {warnings.py:110} WARNING - /home/***/.local/lib/python3.7/site-packages/***/settings.py:250: DeprecationWarning: The sql_alchemy_conn option in [core] has been moved to the sql_alchemy_conn option in [database] - the old setting has been used, but please update your config.
  SQL_ALCHEMY_CONN = conf.get("database", "SQL_ALCHEMY_CONN")

[2023-03-19T21:11:56.097+0000] {warnings.py:110} WARNING - /home/***/.local/lib/python3.7/site-packages/***/utils/sqlalchemy.py:124: DeprecationWarning: The sql_alchemy_conn option in [core] has been moved to the sql_alchemy_conn option in [database] - the old setting has been used, but please update your config.
  return not conf.get("database", "sql_alchemy_conn").startswith("mssql")

[2023-03-19T21:11:56.284+0000] {task_command.py:388} INFO - Running <TaskInstance: project_spark_processing.process_data scheduled__2023-03-18T00:00:00+00:00 [running]> on host 50ce40c43c89
[2023-03-19T21:11:56.721+0000] {taskinstance.py:1511} INFO - Exporting the following env vars:
AIRFLOW_CTX_DAG_OWNER=***
AIRFLOW_CTX_DAG_ID=project_spark_processing
AIRFLOW_CTX_TASK_ID=process_data
AIRFLOW_CTX_EXECUTION_DATE=2023-03-18T00:00:00+00:00
AIRFLOW_CTX_TRY_NUMBER=6
AIRFLOW_CTX_DAG_RUN_ID=scheduled__2023-03-18T00:00:00+00:00
[2023-03-19T21:11:56.722+0000] {dataproc.py:1985} INFO - Submitting job
[2023-03-19T21:11:56.724+0000] {crypto.py:83} WARNING - empty cryptography key - values will not be stored encrypted.
[2023-03-19T21:11:56.725+0000] {base.py:73} INFO - Using connection ID 'google_cloud_default' for task execution.
[2023-03-19T21:11:57.146+0000] {taskinstance.py:1775} ERROR - Task failed with exception
Traceback (most recent call last):
  File "/home/airflow/.local/lib/python3.7/site-packages/google/api_core/grpc_helpers.py", line 50, in error_remapped_callable
    return callable_(*args, **kwargs)
  File "/home/airflow/.local/lib/python3.7/site-packages/grpc/_channel.py", line 946, in __call__
    return _end_unary_response_blocking(state, call, False, None)
  File "/home/airflow/.local/lib/python3.7/site-packages/grpc/_channel.py", line 849, in _end_unary_response_blocking
    raise _InactiveRpcError(state)
grpc._channel._InactiveRpcError: <_InactiveRpcError of RPC that terminated with:
	status = StatusCode.NOT_FOUND
	details = "Not found: Cluster projects/dtc-de-course-375420/regions/europe-west6/clusters/my-dataproc-cluster"
	debug_error_string = "UNKNOWN:Error received from peer ipv4:172.217.168.42:443 {created_time:"2023-03-19T21:11:57.145206558+00:00", grpc_status:5, grpc_message:"Not found: Cluster projects/dtc-de-course-375420/regions/europe-west6/clusters/my-dataproc-cluster"}"
>

The above exception was the direct cause of the following exception:

Traceback (most recent call last):
  File "/home/airflow/.local/lib/python3.7/site-packages/airflow/providers/google/cloud/operators/dataproc.py", line 1994, in execute
    metadata=self.metadata,
  File "/home/airflow/.local/lib/python3.7/site-packages/airflow/providers/google/common/hooks/base_google.py", line 468, in inner_wrapper
    return func(self, *args, **kwargs)
  File "/home/airflow/.local/lib/python3.7/site-packages/airflow/providers/google/cloud/hooks/dataproc.py", line 794, in submit_job
    metadata=metadata,
  File "/home/airflow/.local/lib/python3.7/site-packages/google/cloud/dataproc_v1/services/job_controller/client.py", line 524, in submit_job
    metadata=metadata,
  File "/home/airflow/.local/lib/python3.7/site-packages/google/api_core/gapic_v1/method.py", line 154, in __call__
    return wrapped_func(*args, **kwargs)
  File "/home/airflow/.local/lib/python3.7/site-packages/google/api_core/retry.py", line 288, in retry_wrapped_func
    on_error=on_error,
  File "/home/airflow/.local/lib/python3.7/site-packages/google/api_core/retry.py", line 190, in retry_target
    return target()
  File "/home/airflow/.local/lib/python3.7/site-packages/google/api_core/grpc_helpers.py", line 52, in error_remapped_callable
    raise exceptions.from_grpc_error(exc) from exc
google.api_core.exceptions.NotFound: 404 Not found: Cluster projects/dtc-de-course-375420/regions/europe-west6/clusters/my-dataproc-cluster
[2023-03-19T21:11:57.179+0000] {taskinstance.py:1326} INFO - Marking task as UP_FOR_RETRY. dag_id=project_spark_processing, task_id=process_data, execution_date=20230318T000000, start_date=20230319T211155, end_date=20230319T211157
[2023-03-19T21:11:57.224+0000] {standard_task_runner.py:105} ERROR - Failed to execute job 150 for task process_data (404 Not found: Cluster projects/dtc-de-course-375420/regions/europe-west6/clusters/my-dataproc-cluster; 18089)
[2023-03-19T21:11:57.294+0000] {local_task_job.py:212} INFO - Task exited with return code 1
[2023-03-19T21:11:57.373+0000] {taskinstance.py:2585} INFO - 0 downstream tasks scheduled from follow-on schedule check
