[2023-03-15T19:09:32.478+0000] {taskinstance.py:1084} INFO - Dependencies all met for dep_context=non-requeueable deps ti=<TaskInstance: load_csv_to_bq.load_csv_to_bq scheduled__2023-03-14T00:00:00+00:00 [queued]>
[2023-03-15T19:09:32.491+0000] {taskinstance.py:1084} INFO - Dependencies all met for dep_context=requeueable deps ti=<TaskInstance: load_csv_to_bq.load_csv_to_bq scheduled__2023-03-14T00:00:00+00:00 [queued]>
[2023-03-15T19:09:32.491+0000] {taskinstance.py:1282} INFO - 
--------------------------------------------------------------------------------
[2023-03-15T19:09:32.491+0000] {taskinstance.py:1283} INFO - Starting attempt 1 of 2
[2023-03-15T19:09:32.491+0000] {taskinstance.py:1284} INFO - 
--------------------------------------------------------------------------------
[2023-03-15T19:09:32.510+0000] {taskinstance.py:1303} INFO - Executing <Task(PythonOperator): load_csv_to_bq> on 2023-03-14 00:00:00+00:00
[2023-03-15T19:09:32.521+0000] {standard_task_runner.py:55} INFO - Started process 3198 to run task
[2023-03-15T19:09:32.526+0000] {standard_task_runner.py:82} INFO - Running: ['***', 'tasks', 'run', 'load_csv_to_bq', 'load_csv_to_bq', 'scheduled__2023-03-14T00:00:00+00:00', '--job-id', '12', '--raw', '--subdir', 'DAGS_FOLDER/p_gcs_to_bq.py', '--cfg-path', '/tmp/tmp8diiwyqk']
[2023-03-15T19:09:32.530+0000] {standard_task_runner.py:83} INFO - Job 12: Subtask load_csv_to_bq
[2023-03-15T19:09:32.551+0000] {warnings.py:110} WARNING - /home/***/.local/lib/python3.7/site-packages/***/settings.py:250: DeprecationWarning: The sql_alchemy_conn option in [core] has been moved to the sql_alchemy_conn option in [database] - the old setting has been used, but please update your config.
  SQL_ALCHEMY_CONN = conf.get("database", "SQL_ALCHEMY_CONN")

[2023-03-15T19:09:32.583+0000] {warnings.py:110} WARNING - /home/***/.local/lib/python3.7/site-packages/***/utils/sqlalchemy.py:124: DeprecationWarning: The sql_alchemy_conn option in [core] has been moved to the sql_alchemy_conn option in [database] - the old setting has been used, but please update your config.
  return not conf.get("database", "sql_alchemy_conn").startswith("mssql")

[2023-03-15T19:09:32.628+0000] {task_command.py:388} INFO - Running <TaskInstance: load_csv_to_bq.load_csv_to_bq scheduled__2023-03-14T00:00:00+00:00 [running]> on host 8d6d3f05a6c2
[2023-03-15T19:09:32.737+0000] {taskinstance.py:1511} INFO - Exporting the following env vars:
AIRFLOW_CTX_DAG_OWNER=***
AIRFLOW_CTX_DAG_ID=load_csv_to_bq
AIRFLOW_CTX_TASK_ID=load_csv_to_bq
AIRFLOW_CTX_EXECUTION_DATE=2023-03-14T00:00:00+00:00
AIRFLOW_CTX_TRY_NUMBER=1
AIRFLOW_CTX_DAG_RUN_ID=scheduled__2023-03-14T00:00:00+00:00
[2023-03-15T19:09:32.739+0000] {crypto.py:83} WARNING - empty cryptography key - values will not be stored encrypted.
[2023-03-15T19:09:32.740+0000] {base.py:73} INFO - Using connection ID 'google_cloud_default' for task execution.
[2023-03-15T19:09:32.741+0000] {base.py:73} INFO - Using connection ID 'google_cloud_default' for task execution.
[2023-03-15T19:09:32.897+0000] {taskinstance.py:1775} ERROR - Task failed with exception
Traceback (most recent call last):
  File "/home/airflow/.local/lib/python3.7/site-packages/airflow/operators/python.py", line 175, in execute
    return_value = self.execute_callable()
  File "/home/airflow/.local/lib/python3.7/site-packages/airflow/operators/python.py", line 192, in execute_callable
    return self.python_callable(*self.op_args, **self.op_kwargs)
  File "/opt/airflow/dags/p_gcs_to_bq.py", line 63, in load_csv_to_bq
    bq_hook.insert_rows_from_files(table, source_uris, schema=schema, write_disposition=write_disposition)
AttributeError: 'BigQueryHook' object has no attribute 'insert_rows_from_files'
[2023-03-15T19:09:32.909+0000] {taskinstance.py:1326} INFO - Marking task as UP_FOR_RETRY. dag_id=load_csv_to_bq, task_id=load_csv_to_bq, execution_date=20230314T000000, start_date=20230315T190932, end_date=20230315T190932
[2023-03-15T19:09:32.927+0000] {standard_task_runner.py:105} ERROR - Failed to execute job 12 for task load_csv_to_bq ('BigQueryHook' object has no attribute 'insert_rows_from_files'; 3198)
[2023-03-15T19:09:32.943+0000] {local_task_job.py:212} INFO - Task exited with return code 1
[2023-03-15T19:09:32.971+0000] {taskinstance.py:2585} INFO - 0 downstream tasks scheduled from follow-on schedule check
