[2023-03-20T13:40:54.553+0000] {taskinstance.py:1084} INFO - Dependencies all met for dep_context=non-requeueable deps ti=<TaskInstance: project_transform_bq_data.create_dataproc_cluster manual__2023-03-20T00:12:34.684738+00:00 [queued]>
[2023-03-20T13:40:54.568+0000] {taskinstance.py:1084} INFO - Dependencies all met for dep_context=requeueable deps ti=<TaskInstance: project_transform_bq_data.create_dataproc_cluster manual__2023-03-20T00:12:34.684738+00:00 [queued]>
[2023-03-20T13:40:54.568+0000] {taskinstance.py:1282} INFO - 
--------------------------------------------------------------------------------
[2023-03-20T13:40:54.568+0000] {taskinstance.py:1283} INFO - Starting attempt 3 of 3
[2023-03-20T13:40:54.569+0000] {taskinstance.py:1284} INFO - 
--------------------------------------------------------------------------------
[2023-03-20T13:40:54.590+0000] {taskinstance.py:1303} INFO - Executing <Task(DataprocCreateClusterOperator): create_dataproc_cluster> on 2023-03-20 00:12:34.684738+00:00
[2023-03-20T13:40:54.599+0000] {standard_task_runner.py:55} INFO - Started process 95 to run task
[2023-03-20T13:40:54.607+0000] {standard_task_runner.py:82} INFO - Running: ['***', 'tasks', 'run', 'project_transform_bq_data', 'create_dataproc_cluster', 'manual__2023-03-20T00:12:34.684738+00:00', '--job-id', '179', '--raw', '--subdir', 'DAGS_FOLDER/p_spark_processing.py', '--cfg-path', '/tmp/tmphdibqwze']
[2023-03-20T13:40:54.610+0000] {standard_task_runner.py:83} INFO - Job 179: Subtask create_dataproc_cluster
[2023-03-20T13:40:54.630+0000] {warnings.py:110} WARNING - /home/***/.local/lib/python3.7/site-packages/***/settings.py:250: DeprecationWarning: The sql_alchemy_conn option in [core] has been moved to the sql_alchemy_conn option in [database] - the old setting has been used, but please update your config.
  SQL_ALCHEMY_CONN = conf.get("database", "SQL_ALCHEMY_CONN")

[2023-03-20T13:40:54.707+0000] {task_command.py:388} INFO - Running <TaskInstance: project_transform_bq_data.create_dataproc_cluster manual__2023-03-20T00:12:34.684738+00:00 [running]> on host 4fd00a82f4e9
[2023-03-20T13:40:54.822+0000] {taskinstance.py:1511} INFO - Exporting the following env vars:
AIRFLOW_CTX_DAG_OWNER=***
AIRFLOW_CTX_DAG_ID=project_transform_bq_data
AIRFLOW_CTX_TASK_ID=create_dataproc_cluster
AIRFLOW_CTX_EXECUTION_DATE=2023-03-20T00:12:34.684738+00:00
AIRFLOW_CTX_TRY_NUMBER=3
AIRFLOW_CTX_DAG_RUN_ID=manual__2023-03-20T00:12:34.684738+00:00
[2023-03-20T13:40:54.824+0000] {dataproc.py:601} INFO - Creating cluster: my-dataproc-cluster
[2023-03-20T13:40:54.827+0000] {crypto.py:83} WARNING - empty cryptography key - values will not be stored encrypted.
[2023-03-20T13:40:54.828+0000] {base.py:73} INFO - Using connection ID 'google_cloud_default' for task execution.
[2023-03-20T13:40:56.215+0000] {taskinstance.py:1775} ERROR - Task failed with exception
Traceback (most recent call last):
  File "/home/airflow/.local/lib/python3.7/site-packages/google/api_core/grpc_helpers.py", line 50, in error_remapped_callable
    return callable_(*args, **kwargs)
  File "/home/airflow/.local/lib/python3.7/site-packages/grpc/_channel.py", line 946, in __call__
    return _end_unary_response_blocking(state, call, False, None)
  File "/home/airflow/.local/lib/python3.7/site-packages/grpc/_channel.py", line 849, in _end_unary_response_blocking
    raise _InactiveRpcError(state)
grpc._channel._InactiveRpcError: <_InactiveRpcError of RPC that terminated with:
	status = StatusCode.INVALID_ARGUMENT
	details = "Multiple validation errors:
 - Insufficient 'CPUS' quota. Requested 8.0, available 6.0.
 - Insufficient 'CPUS_ALL_REGIONS' quota. Requested 12.0, available 10.0.
 - Insufficient 'DISKS_TOTAL_GB' quota. Requested 2548.0, available 2048.0.
 - This request exceeds CPU quota. Some things to try: request fewer workers (a minimum of 2 is required), use smaller master and/or worker machine types (such as n1-standard-2)."
	debug_error_string = "UNKNOWN:Error received from peer ipv4:172.217.168.10:443 {created_time:"2023-03-20T13:40:56.213923774+00:00", grpc_status:3, grpc_message:"Multiple validation errors:\n - Insufficient \'CPUS\' quota. Requested 8.0, available 6.0.\n - Insufficient \'CPUS_ALL_REGIONS\' quota. Requested 12.0, available 10.0.\n - Insufficient \'DISKS_TOTAL_GB\' quota. Requested 2548.0, available 2048.0.\n - This request exceeds CPU quota. Some things to try: request fewer workers (a minimum of 2 is required), use smaller master and/or worker machine types (such as n1-standard-2)."}"
>

The above exception was the direct cause of the following exception:

Traceback (most recent call last):
  File "/home/airflow/.local/lib/python3.7/site-packages/airflow/providers/google/cloud/operators/dataproc.py", line 609, in execute
    operation = self._create_cluster(hook)
  File "/home/airflow/.local/lib/python3.7/site-packages/airflow/providers/google/cloud/operators/dataproc.py", line 545, in _create_cluster
    metadata=self.metadata,
  File "/home/airflow/.local/lib/python3.7/site-packages/airflow/providers/google/common/hooks/base_google.py", line 468, in inner_wrapper
    return func(self, *args, **kwargs)
  File "/home/airflow/.local/lib/python3.7/site-packages/airflow/providers/google/cloud/hooks/dataproc.py", line 341, in create_cluster
    metadata=metadata,
  File "/home/airflow/.local/lib/python3.7/site-packages/google/cloud/dataproc_v1/services/cluster_controller/client.py", line 564, in create_cluster
    metadata=metadata,
  File "/home/airflow/.local/lib/python3.7/site-packages/google/api_core/gapic_v1/method.py", line 154, in __call__
    return wrapped_func(*args, **kwargs)
  File "/home/airflow/.local/lib/python3.7/site-packages/google/api_core/retry.py", line 288, in retry_wrapped_func
    on_error=on_error,
  File "/home/airflow/.local/lib/python3.7/site-packages/google/api_core/retry.py", line 190, in retry_target
    return target()
  File "/home/airflow/.local/lib/python3.7/site-packages/google/api_core/timeout.py", line 99, in func_with_timeout
    return func(*args, **kwargs)
  File "/home/airflow/.local/lib/python3.7/site-packages/google/api_core/grpc_helpers.py", line 52, in error_remapped_callable
    raise exceptions.from_grpc_error(exc) from exc
google.api_core.exceptions.InvalidArgument: 400 Multiple validation errors:
 - Insufficient 'CPUS' quota. Requested 8.0, available 6.0.
 - Insufficient 'CPUS_ALL_REGIONS' quota. Requested 12.0, available 10.0.
 - Insufficient 'DISKS_TOTAL_GB' quota. Requested 2548.0, available 2048.0.
 - This request exceeds CPU quota. Some things to try: request fewer workers (a minimum of 2 is required), use smaller master and/or worker machine types (such as n1-standard-2).
[2023-03-20T13:40:56.233+0000] {taskinstance.py:1326} INFO - Marking task as FAILED. dag_id=project_transform_bq_data, task_id=create_dataproc_cluster, execution_date=20230320T001234, start_date=20230320T134054, end_date=20230320T134056
[2023-03-20T13:40:56.251+0000] {standard_task_runner.py:105} ERROR - Failed to execute job 179 for task create_dataproc_cluster (400 Multiple validation errors:
 - Insufficient 'CPUS' quota. Requested 8.0, available 6.0.
 - Insufficient 'CPUS_ALL_REGIONS' quota. Requested 12.0, available 10.0.
 - Insufficient 'DISKS_TOTAL_GB' quota. Requested 2548.0, available 2048.0.
 - This request exceeds CPU quota. Some things to try: request fewer workers (a minimum of 2 is required), use smaller master and/or worker machine types (such as n1-standard-2).; 95)
[2023-03-20T13:40:56.304+0000] {local_task_job.py:212} INFO - Task exited with return code 1
[2023-03-20T13:40:56.331+0000] {taskinstance.py:2585} INFO - 0 downstream tasks scheduled from follow-on schedule check
