[2023-03-20T14:16:29.205+0000] {taskinstance.py:1084} INFO - Dependencies all met for dep_context=non-requeueable deps ti=<TaskInstance: project_transform_bq_data.create_dataproc_cluster manual__2023-03-20T00:12:34.684738+00:00 [queued]>
[2023-03-20T14:16:29.244+0000] {taskinstance.py:1084} INFO - Dependencies all met for dep_context=requeueable deps ti=<TaskInstance: project_transform_bq_data.create_dataproc_cluster manual__2023-03-20T00:12:34.684738+00:00 [queued]>
[2023-03-20T14:16:29.249+0000] {taskinstance.py:1282} INFO - 
--------------------------------------------------------------------------------
[2023-03-20T14:16:29.257+0000] {taskinstance.py:1283} INFO - Starting attempt 10 of 11
[2023-03-20T14:16:29.265+0000] {taskinstance.py:1284} INFO - 
--------------------------------------------------------------------------------
[2023-03-20T14:16:29.324+0000] {taskinstance.py:1303} INFO - Executing <Task(DataprocCreateClusterOperator): create_dataproc_cluster> on 2023-03-20 00:12:34.684738+00:00
[2023-03-20T14:16:29.347+0000] {standard_task_runner.py:55} INFO - Started process 1631 to run task
[2023-03-20T14:16:29.367+0000] {standard_task_runner.py:82} INFO - Running: ['***', 'tasks', 'run', 'project_transform_bq_data', 'create_dataproc_cluster', 'manual__2023-03-20T00:12:34.684738+00:00', '--job-id', '189', '--raw', '--subdir', 'DAGS_FOLDER/p_spark_processing.py', '--cfg-path', '/tmp/tmpi2jviqzk']
[2023-03-20T14:16:29.389+0000] {standard_task_runner.py:83} INFO - Job 189: Subtask create_dataproc_cluster
[2023-03-20T14:16:29.441+0000] {warnings.py:110} WARNING - /home/***/.local/lib/python3.7/site-packages/***/settings.py:250: DeprecationWarning: The sql_alchemy_conn option in [core] has been moved to the sql_alchemy_conn option in [database] - the old setting has been used, but please update your config.
  SQL_ALCHEMY_CONN = conf.get("database", "SQL_ALCHEMY_CONN")

[2023-03-20T14:16:29.646+0000] {task_command.py:388} INFO - Running <TaskInstance: project_transform_bq_data.create_dataproc_cluster manual__2023-03-20T00:12:34.684738+00:00 [running]> on host 4fd00a82f4e9
[2023-03-20T14:16:29.970+0000] {taskinstance.py:1511} INFO - Exporting the following env vars:
AIRFLOW_CTX_DAG_OWNER=***
AIRFLOW_CTX_DAG_ID=project_transform_bq_data
AIRFLOW_CTX_TASK_ID=create_dataproc_cluster
AIRFLOW_CTX_EXECUTION_DATE=2023-03-20T00:12:34.684738+00:00
AIRFLOW_CTX_TRY_NUMBER=10
AIRFLOW_CTX_DAG_RUN_ID=manual__2023-03-20T00:12:34.684738+00:00
[2023-03-20T14:16:29.973+0000] {dataproc.py:601} INFO - Creating cluster: my-dataproc-cluster
[2023-03-20T14:16:29.977+0000] {crypto.py:83} WARNING - empty cryptography key - values will not be stored encrypted.
[2023-03-20T14:16:29.978+0000] {base.py:73} INFO - Using connection ID 'google_cloud_default' for task execution.
[2023-03-20T14:16:30.249+0000] {taskinstance.py:1775} ERROR - Task failed with exception
Traceback (most recent call last):
  File "/home/airflow/.local/lib/python3.7/site-packages/google/api_core/grpc_helpers.py", line 50, in error_remapped_callable
    return callable_(*args, **kwargs)
  File "/home/airflow/.local/lib/python3.7/site-packages/grpc/_channel.py", line 946, in __call__
    return _end_unary_response_blocking(state, call, False, None)
  File "/home/airflow/.local/lib/python3.7/site-packages/grpc/_channel.py", line 849, in _end_unary_response_blocking
    raise _InactiveRpcError(state)
grpc._channel._InactiveRpcError: <_InactiveRpcError of RPC that terminated with:
	status = StatusCode.INVALID_ARGUMENT
	details = "Worker configuration must contain two or more workers: '1'"
	debug_error_string = "UNKNOWN:Error received from peer ipv4:216.58.215.234:443 {grpc_message:"Worker configuration must contain two or more workers: \'1\'", grpc_status:3, created_time:"2023-03-20T14:16:30.248228124+00:00"}"
>

The above exception was the direct cause of the following exception:

Traceback (most recent call last):
  File "/home/airflow/.local/lib/python3.7/site-packages/airflow/providers/google/cloud/operators/dataproc.py", line 609, in execute
    operation = self._create_cluster(hook)
  File "/home/airflow/.local/lib/python3.7/site-packages/airflow/providers/google/cloud/operators/dataproc.py", line 545, in _create_cluster
    metadata=self.metadata,
  File "/home/airflow/.local/lib/python3.7/site-packages/airflow/providers/google/common/hooks/base_google.py", line 468, in inner_wrapper
    return func(self, *args, **kwargs)
  File "/home/airflow/.local/lib/python3.7/site-packages/airflow/providers/google/cloud/hooks/dataproc.py", line 341, in create_cluster
    metadata=metadata,
  File "/home/airflow/.local/lib/python3.7/site-packages/google/cloud/dataproc_v1/services/cluster_controller/client.py", line 564, in create_cluster
    metadata=metadata,
  File "/home/airflow/.local/lib/python3.7/site-packages/google/api_core/gapic_v1/method.py", line 154, in __call__
    return wrapped_func(*args, **kwargs)
  File "/home/airflow/.local/lib/python3.7/site-packages/google/api_core/retry.py", line 288, in retry_wrapped_func
    on_error=on_error,
  File "/home/airflow/.local/lib/python3.7/site-packages/google/api_core/retry.py", line 190, in retry_target
    return target()
  File "/home/airflow/.local/lib/python3.7/site-packages/google/api_core/timeout.py", line 99, in func_with_timeout
    return func(*args, **kwargs)
  File "/home/airflow/.local/lib/python3.7/site-packages/google/api_core/grpc_helpers.py", line 52, in error_remapped_callable
    raise exceptions.from_grpc_error(exc) from exc
google.api_core.exceptions.InvalidArgument: 400 Worker configuration must contain two or more workers: '1'
[2023-03-20T14:16:30.271+0000] {taskinstance.py:1326} INFO - Marking task as UP_FOR_RETRY. dag_id=project_transform_bq_data, task_id=create_dataproc_cluster, execution_date=20230320T001234, start_date=20230320T141629, end_date=20230320T141630
[2023-03-20T14:16:30.304+0000] {standard_task_runner.py:105} ERROR - Failed to execute job 189 for task create_dataproc_cluster (400 Worker configuration must contain two or more workers: '1'; 1631)
[2023-03-20T14:16:30.351+0000] {local_task_job.py:212} INFO - Task exited with return code 1
[2023-03-20T14:16:30.390+0000] {taskinstance.py:2585} INFO - 0 downstream tasks scheduled from follow-on schedule check
