[2023-03-21T12:19:57.199+0000] {taskinstance.py:1084} INFO - Dependencies all met for dep_context=non-requeueable deps ti=<TaskInstance: project_masterdag.spark_processing manual__2023-03-21T10:53:30.802707+00:00 [queued]>
[2023-03-21T12:19:57.233+0000] {taskinstance.py:1084} INFO - Dependencies all met for dep_context=requeueable deps ti=<TaskInstance: project_masterdag.spark_processing manual__2023-03-21T10:53:30.802707+00:00 [queued]>
[2023-03-21T12:19:57.241+0000] {taskinstance.py:1282} INFO - 
--------------------------------------------------------------------------------
[2023-03-21T12:19:57.241+0000] {taskinstance.py:1283} INFO - Starting attempt 7 of 8
[2023-03-21T12:19:57.241+0000] {taskinstance.py:1284} INFO - 
--------------------------------------------------------------------------------
[2023-03-21T12:19:57.302+0000] {taskinstance.py:1303} INFO - Executing <Task(DataprocSubmitJobOperator): spark_processing> on 2023-03-21 10:53:30.802707+00:00
[2023-03-21T12:19:57.317+0000] {standard_task_runner.py:55} INFO - Started process 34466 to run task
[2023-03-21T12:19:57.334+0000] {standard_task_runner.py:82} INFO - Running: ['***', 'tasks', 'run', 'project_masterdag', 'spark_processing', 'manual__2023-03-21T10:53:30.802707+00:00', '--job-id', '303', '--raw', '--subdir', 'DAGS_FOLDER/project_master_dags.py', '--cfg-path', '/tmp/tmpdxclyses']
[2023-03-21T12:19:57.339+0000] {standard_task_runner.py:83} INFO - Job 303: Subtask spark_processing
[2023-03-21T12:19:57.380+0000] {warnings.py:110} WARNING - /home/***/.local/lib/python3.7/site-packages/***/settings.py:250: DeprecationWarning: The sql_alchemy_conn option in [core] has been moved to the sql_alchemy_conn option in [database] - the old setting has been used, but please update your config.
  SQL_ALCHEMY_CONN = conf.get("database", "SQL_ALCHEMY_CONN")

[2023-03-21T12:19:57.572+0000] {task_command.py:388} INFO - Running <TaskInstance: project_masterdag.spark_processing manual__2023-03-21T10:53:30.802707+00:00 [running]> on host 796cac132c25
[2023-03-21T12:19:57.858+0000] {taskinstance.py:1511} INFO - Exporting the following env vars:
AIRFLOW_CTX_DAG_OWNER=***
AIRFLOW_CTX_DAG_ID=project_masterdag
AIRFLOW_CTX_TASK_ID=spark_processing
AIRFLOW_CTX_EXECUTION_DATE=2023-03-21T10:53:30.802707+00:00
AIRFLOW_CTX_TRY_NUMBER=7
AIRFLOW_CTX_DAG_RUN_ID=manual__2023-03-21T10:53:30.802707+00:00
[2023-03-21T12:19:57.860+0000] {dataproc.py:1985} INFO - Submitting job
[2023-03-21T12:19:57.862+0000] {base.py:73} INFO - Using connection ID 'google_cloud_default' for task execution.
[2023-03-21T12:19:58.198+0000] {dataproc.py:1997} INFO - Job transform_bq_data submitted successfully.
[2023-03-21T12:19:58.238+0000] {dataproc.py:2017} INFO - Waiting for job transform_bq_data to complete
[2023-03-21T12:23:36.482+0000] {local_task_job.py:277} WARNING - State of this instance has been externally set to restarting. Terminating instance.
[2023-03-21T12:23:36.485+0000] {process_utils.py:133} INFO - Sending Signals.SIGTERM to group 34466. PIDs of all processes in the group: [34466]
[2023-03-21T12:23:36.486+0000] {process_utils.py:84} INFO - Sending the signal Signals.SIGTERM to group 34466
[2023-03-21T12:23:36.486+0000] {taskinstance.py:1482} ERROR - Received SIGTERM. Terminating subprocesses.
[2023-03-21T12:23:36.616+0000] {taskinstance.py:1775} ERROR - Task failed with exception
Traceback (most recent call last):
  File "/home/airflow/.local/lib/python3.7/site-packages/airflow/models/taskinstance.py", line 1523, in _execute_task_with_callbacks
    result = self._execute_task(context, task_orig)
  File "/home/airflow/.local/lib/python3.7/site-packages/airflow/models/taskinstance.py", line 1588, in _execute_task
    result = execute_callable(context=context)
  File "/home/airflow/.local/lib/python3.7/site-packages/airflow/providers/google/cloud/operators/dataproc.py", line 2019, in execute
    job_id=new_job_id, region=self.region, project_id=self.project_id, timeout=self.wait_timeout
  File "/home/airflow/.local/lib/python3.7/site-packages/airflow/providers/google/common/hooks/base_google.py", line 468, in inner_wrapper
    return func(self, *args, **kwargs)
  File "/home/airflow/.local/lib/python3.7/site-packages/airflow/providers/google/cloud/hooks/dataproc.py", line 715, in wait_for_job
    time.sleep(wait_time)
  File "/home/airflow/.local/lib/python3.7/site-packages/airflow/models/taskinstance.py", line 1483, in signal_handler
    raise AirflowTermSignal("Task received SIGTERM signal")
airflow.exceptions.AirflowTermSignal: Task received SIGTERM signal

During handling of the above exception, another exception occurred:

Traceback (most recent call last):
  File "/home/airflow/.local/lib/python3.7/site-packages/airflow/models/taskinstance.py", line 1377, in _run_raw_task
    self._execute_task_with_callbacks(context, test_mode)
  File "/home/airflow/.local/lib/python3.7/site-packages/airflow/models/taskinstance.py", line 1530, in _execute_task_with_callbacks
    raise AirflowException("Task received SIGTERM signal")
airflow.exceptions.AirflowException: Task received SIGTERM signal
[2023-03-21T12:23:36.642+0000] {taskinstance.py:1326} INFO - Marking task as UP_FOR_RETRY. dag_id=project_masterdag, task_id=spark_processing, execution_date=20230321T105330, start_date=20230321T121957, end_date=20230321T122336
[2023-03-21T12:23:36.677+0000] {standard_task_runner.py:105} ERROR - Failed to execute job 303 for task spark_processing (Task received SIGTERM signal; 34466)
[2023-03-21T12:23:36.712+0000] {process_utils.py:79} INFO - Process psutil.Process(pid=34466, status='terminated', exitcode=1, started='12:19:56') (34466) terminated with exit code 1
