[2023-03-21T12:19:12.190+0000] {taskinstance.py:1084} INFO - Dependencies all met for dep_context=non-requeueable deps ti=<TaskInstance: project_masterdag.spark_processing manual__2023-03-21T10:53:30.802707+00:00 [queued]>
[2023-03-21T12:19:12.231+0000] {taskinstance.py:1084} INFO - Dependencies all met for dep_context=requeueable deps ti=<TaskInstance: project_masterdag.spark_processing manual__2023-03-21T10:53:30.802707+00:00 [queued]>
[2023-03-21T12:19:12.232+0000] {taskinstance.py:1282} INFO - 
--------------------------------------------------------------------------------
[2023-03-21T12:19:12.232+0000] {taskinstance.py:1283} INFO - Starting attempt 6 of 7
[2023-03-21T12:19:12.232+0000] {taskinstance.py:1284} INFO - 
--------------------------------------------------------------------------------
[2023-03-21T12:19:12.292+0000] {taskinstance.py:1303} INFO - Executing <Task(DataprocSubmitJobOperator): spark_processing> on 2023-03-21 10:53:30.802707+00:00
[2023-03-21T12:19:12.318+0000] {standard_task_runner.py:55} INFO - Started process 34418 to run task
[2023-03-21T12:19:12.336+0000] {standard_task_runner.py:82} INFO - Running: ['***', 'tasks', 'run', 'project_masterdag', 'spark_processing', 'manual__2023-03-21T10:53:30.802707+00:00', '--job-id', '302', '--raw', '--subdir', 'DAGS_FOLDER/project_master_dags.py', '--cfg-path', '/tmp/tmpz1pdrdj6']
[2023-03-21T12:19:12.344+0000] {standard_task_runner.py:83} INFO - Job 302: Subtask spark_processing
[2023-03-21T12:19:12.384+0000] {warnings.py:110} WARNING - /home/***/.local/lib/python3.7/site-packages/***/settings.py:250: DeprecationWarning: The sql_alchemy_conn option in [core] has been moved to the sql_alchemy_conn option in [database] - the old setting has been used, but please update your config.
  SQL_ALCHEMY_CONN = conf.get("database", "SQL_ALCHEMY_CONN")

[2023-03-21T12:19:12.630+0000] {task_command.py:388} INFO - Running <TaskInstance: project_masterdag.spark_processing manual__2023-03-21T10:53:30.802707+00:00 [running]> on host 796cac132c25
[2023-03-21T12:19:12.965+0000] {taskinstance.py:1511} INFO - Exporting the following env vars:
AIRFLOW_CTX_DAG_OWNER=***
AIRFLOW_CTX_DAG_ID=project_masterdag
AIRFLOW_CTX_TASK_ID=spark_processing
AIRFLOW_CTX_EXECUTION_DATE=2023-03-21T10:53:30.802707+00:00
AIRFLOW_CTX_TRY_NUMBER=6
AIRFLOW_CTX_DAG_RUN_ID=manual__2023-03-21T10:53:30.802707+00:00
[2023-03-21T12:19:12.966+0000] {dataproc.py:1985} INFO - Submitting job
[2023-03-21T12:19:12.968+0000] {base.py:73} INFO - Using connection ID 'google_cloud_default' for task execution.
[2023-03-21T12:19:13.313+0000] {taskinstance.py:1775} ERROR - Task failed with exception
Traceback (most recent call last):
  File "/home/airflow/.local/lib/python3.7/site-packages/google/api_core/grpc_helpers.py", line 50, in error_remapped_callable
    return callable_(*args, **kwargs)
  File "/home/airflow/.local/lib/python3.7/site-packages/grpc/_channel.py", line 946, in __call__
    return _end_unary_response_blocking(state, call, False, None)
  File "/home/airflow/.local/lib/python3.7/site-packages/grpc/_channel.py", line 849, in _end_unary_response_blocking
    raise _InactiveRpcError(state)
grpc._channel._InactiveRpcError: <_InactiveRpcError of RPC that terminated with:
	status = StatusCode.ALREADY_EXISTS
	details = "Already exists: Failed to submit job: Job projects/dtc-de-course-375420/regions/europe-west6/jobs/transform_bq_data"
	debug_error_string = "UNKNOWN:Error received from peer ipv4:172.217.168.74:443 {created_time:"2023-03-21T12:19:13.312493004+00:00", grpc_status:6, grpc_message:"Already exists: Failed to submit job: Job projects/dtc-de-course-375420/regions/europe-west6/jobs/transform_bq_data"}"
>

The above exception was the direct cause of the following exception:

Traceback (most recent call last):
  File "/home/airflow/.local/lib/python3.7/site-packages/airflow/providers/google/cloud/operators/dataproc.py", line 1994, in execute
    metadata=self.metadata,
  File "/home/airflow/.local/lib/python3.7/site-packages/airflow/providers/google/common/hooks/base_google.py", line 468, in inner_wrapper
    return func(self, *args, **kwargs)
  File "/home/airflow/.local/lib/python3.7/site-packages/airflow/providers/google/cloud/hooks/dataproc.py", line 794, in submit_job
    metadata=metadata,
  File "/home/airflow/.local/lib/python3.7/site-packages/google/cloud/dataproc_v1/services/job_controller/client.py", line 524, in submit_job
    metadata=metadata,
  File "/home/airflow/.local/lib/python3.7/site-packages/google/api_core/gapic_v1/method.py", line 154, in __call__
    return wrapped_func(*args, **kwargs)
  File "/home/airflow/.local/lib/python3.7/site-packages/google/api_core/retry.py", line 288, in retry_wrapped_func
    on_error=on_error,
  File "/home/airflow/.local/lib/python3.7/site-packages/google/api_core/retry.py", line 190, in retry_target
    return target()
  File "/home/airflow/.local/lib/python3.7/site-packages/google/api_core/grpc_helpers.py", line 52, in error_remapped_callable
    raise exceptions.from_grpc_error(exc) from exc
google.api_core.exceptions.AlreadyExists: 409 Already exists: Failed to submit job: Job projects/dtc-de-course-375420/regions/europe-west6/jobs/transform_bq_data
[2023-03-21T12:19:13.340+0000] {taskinstance.py:1326} INFO - Marking task as UP_FOR_RETRY. dag_id=project_masterdag, task_id=spark_processing, execution_date=20230321T105330, start_date=20230321T121912, end_date=20230321T121913
[2023-03-21T12:19:13.385+0000] {standard_task_runner.py:105} ERROR - Failed to execute job 302 for task spark_processing (409 Already exists: Failed to submit job: Job projects/dtc-de-course-375420/regions/europe-west6/jobs/transform_bq_data; 34418)
[2023-03-21T12:19:13.443+0000] {local_task_job.py:212} INFO - Task exited with return code 1
[2023-03-21T12:19:13.491+0000] {taskinstance.py:2585} INFO - 0 downstream tasks scheduled from follow-on schedule check
