[2023-03-18T00:22:21.620+0000] {taskinstance.py:1084} INFO - Dependencies all met for dep_context=non-requeueable deps ti=<TaskInstance: transform_bq_data.create_dataproc_cluster manual__2023-03-18T00:22:20.257510+00:00 [queued]>
[2023-03-18T00:22:21.634+0000] {taskinstance.py:1084} INFO - Dependencies all met for dep_context=requeueable deps ti=<TaskInstance: transform_bq_data.create_dataproc_cluster manual__2023-03-18T00:22:20.257510+00:00 [queued]>
[2023-03-18T00:22:21.634+0000] {taskinstance.py:1282} INFO - 
--------------------------------------------------------------------------------
[2023-03-18T00:22:21.634+0000] {taskinstance.py:1283} INFO - Starting attempt 1 of 2
[2023-03-18T00:22:21.634+0000] {taskinstance.py:1284} INFO - 
--------------------------------------------------------------------------------
[2023-03-18T00:22:21.658+0000] {taskinstance.py:1303} INFO - Executing <Task(DataprocCreateClusterOperator): create_dataproc_cluster> on 2023-03-18 00:22:20.257510+00:00
[2023-03-18T00:22:21.665+0000] {standard_task_runner.py:55} INFO - Started process 994 to run task
[2023-03-18T00:22:21.672+0000] {standard_task_runner.py:82} INFO - Running: ['***', 'tasks', 'run', 'transform_bq_data', 'create_dataproc_cluster', 'manual__2023-03-18T00:22:20.257510+00:00', '--job-id', '61', '--raw', '--subdir', 'DAGS_FOLDER/p_spark_processing.py', '--cfg-path', '/tmp/tmpuiowq3cp']
[2023-03-18T00:22:21.675+0000] {standard_task_runner.py:83} INFO - Job 61: Subtask create_dataproc_cluster
[2023-03-18T00:22:21.696+0000] {warnings.py:110} WARNING - /home/***/.local/lib/python3.7/site-packages/***/settings.py:250: DeprecationWarning: The sql_alchemy_conn option in [core] has been moved to the sql_alchemy_conn option in [database] - the old setting has been used, but please update your config.
  SQL_ALCHEMY_CONN = conf.get("database", "SQL_ALCHEMY_CONN")

[2023-03-18T00:22:21.769+0000] {task_command.py:388} INFO - Running <TaskInstance: transform_bq_data.create_dataproc_cluster manual__2023-03-18T00:22:20.257510+00:00 [running]> on host 8d6d3f05a6c2
[2023-03-18T00:22:21.888+0000] {taskinstance.py:1511} INFO - Exporting the following env vars:
AIRFLOW_CTX_DAG_OWNER=***
AIRFLOW_CTX_DAG_ID=transform_bq_data
AIRFLOW_CTX_TASK_ID=create_dataproc_cluster
AIRFLOW_CTX_EXECUTION_DATE=2023-03-18T00:22:20.257510+00:00
AIRFLOW_CTX_TRY_NUMBER=1
AIRFLOW_CTX_DAG_RUN_ID=manual__2023-03-18T00:22:20.257510+00:00
[2023-03-18T00:22:21.889+0000] {dataproc.py:601} INFO - Creating cluster: dataproc-cluster
[2023-03-18T00:22:21.890+0000] {crypto.py:83} WARNING - empty cryptography key - values will not be stored encrypted.
[2023-03-18T00:22:21.891+0000] {base.py:73} INFO - Using connection ID 'google_cloud_default' for task execution.
[2023-03-18T00:22:22.865+0000] {taskinstance.py:1775} ERROR - Task failed with exception
Traceback (most recent call last):
  File "/home/airflow/.local/lib/python3.7/site-packages/google/api_core/grpc_helpers.py", line 50, in error_remapped_callable
    return callable_(*args, **kwargs)
  File "/home/airflow/.local/lib/python3.7/site-packages/grpc/_channel.py", line 946, in __call__
    return _end_unary_response_blocking(state, call, False, None)
  File "/home/airflow/.local/lib/python3.7/site-packages/grpc/_channel.py", line 849, in _end_unary_response_blocking
    raise _InactiveRpcError(state)
grpc._channel._InactiveRpcError: <_InactiveRpcError of RPC that terminated with:
	status = StatusCode.PERMISSION_DENIED
	details = "Cloud Dataproc API has not been used in project 192108012555 before or it is disabled. Enable it by visiting https://console.developers.google.com/apis/api/dataproc.googleapis.com/overview?project=192108012555 then retry. If you enabled this API recently, wait a few minutes for the action to propagate to our systems and retry."
	debug_error_string = "UNKNOWN:Error received from peer ipv4:172.217.168.74:443 {created_time:"2023-03-18T00:22:22.863254664+00:00", grpc_status:7, grpc_message:"Cloud Dataproc API has not been used in project 192108012555 before or it is disabled. Enable it by visiting https://console.developers.google.com/apis/api/dataproc.googleapis.com/overview?project=192108012555 then retry. If you enabled this API recently, wait a few minutes for the action to propagate to our systems and retry."}"
>

The above exception was the direct cause of the following exception:

Traceback (most recent call last):
  File "/home/airflow/.local/lib/python3.7/site-packages/airflow/providers/google/cloud/operators/dataproc.py", line 609, in execute
    operation = self._create_cluster(hook)
  File "/home/airflow/.local/lib/python3.7/site-packages/airflow/providers/google/cloud/operators/dataproc.py", line 545, in _create_cluster
    metadata=self.metadata,
  File "/home/airflow/.local/lib/python3.7/site-packages/airflow/providers/google/common/hooks/base_google.py", line 468, in inner_wrapper
    return func(self, *args, **kwargs)
  File "/home/airflow/.local/lib/python3.7/site-packages/airflow/providers/google/cloud/hooks/dataproc.py", line 341, in create_cluster
    metadata=metadata,
  File "/home/airflow/.local/lib/python3.7/site-packages/google/cloud/dataproc_v1/services/cluster_controller/client.py", line 564, in create_cluster
    metadata=metadata,
  File "/home/airflow/.local/lib/python3.7/site-packages/google/api_core/gapic_v1/method.py", line 154, in __call__
    return wrapped_func(*args, **kwargs)
  File "/home/airflow/.local/lib/python3.7/site-packages/google/api_core/retry.py", line 288, in retry_wrapped_func
    on_error=on_error,
  File "/home/airflow/.local/lib/python3.7/site-packages/google/api_core/retry.py", line 190, in retry_target
    return target()
  File "/home/airflow/.local/lib/python3.7/site-packages/google/api_core/timeout.py", line 99, in func_with_timeout
    return func(*args, **kwargs)
  File "/home/airflow/.local/lib/python3.7/site-packages/google/api_core/grpc_helpers.py", line 52, in error_remapped_callable
    raise exceptions.from_grpc_error(exc) from exc
google.api_core.exceptions.PermissionDenied: 403 Cloud Dataproc API has not been used in project 192108012555 before or it is disabled. Enable it by visiting https://console.developers.google.com/apis/api/dataproc.googleapis.com/overview?project=192108012555 then retry. If you enabled this API recently, wait a few minutes for the action to propagate to our systems and retry. [links {
  description: "Google developers console API activation"
  url: "https://console.developers.google.com/apis/api/dataproc.googleapis.com/overview?project=192108012555"
}
, reason: "SERVICE_DISABLED"
domain: "googleapis.com"
metadata {
  key: "consumer"
  value: "projects/192108012555"
}
metadata {
  key: "service"
  value: "dataproc.googleapis.com"
}
]
[2023-03-18T00:22:22.886+0000] {taskinstance.py:1326} INFO - Marking task as UP_FOR_RETRY. dag_id=transform_bq_data, task_id=create_dataproc_cluster, execution_date=20230318T002220, start_date=20230318T002221, end_date=20230318T002222
[2023-03-18T00:22:22.908+0000] {standard_task_runner.py:105} ERROR - Failed to execute job 61 for task create_dataproc_cluster (403 Cloud Dataproc API has not been used in project 192108012555 before or it is disabled. Enable it by visiting https://console.developers.google.com/apis/api/dataproc.googleapis.com/overview?project=192108012555 then retry. If you enabled this API recently, wait a few minutes for the action to propagate to our systems and retry. [links {
  description: "Google developers console API activation"
  url: "https://console.developers.google.com/apis/api/dataproc.googleapis.com/overview?project=192108012555"
}
, reason: "SERVICE_DISABLED"
domain: "googleapis.com"
metadata {
  key: "consumer"
  value: "projects/192108012555"
}
metadata {
  key: "service"
  value: "dataproc.googleapis.com"
}
]; 994)
[2023-03-18T00:22:22.929+0000] {local_task_job.py:212} INFO - Task exited with return code 1
[2023-03-18T00:22:22.964+0000] {taskinstance.py:2585} INFO - 0 downstream tasks scheduled from follow-on schedule check
