[2023-03-18T13:14:51.165+0000] {taskinstance.py:1084} INFO - Dependencies all met for dep_context=non-requeueable deps ti=<TaskInstance: transform_bq_data.create_dataproc_cluster manual__2023-03-18T00:22:20.257510+00:00 [queued]>
[2023-03-18T13:14:51.179+0000] {taskinstance.py:1084} INFO - Dependencies all met for dep_context=requeueable deps ti=<TaskInstance: transform_bq_data.create_dataproc_cluster manual__2023-03-18T00:22:20.257510+00:00 [queued]>
[2023-03-18T13:14:51.179+0000] {taskinstance.py:1282} INFO - 
--------------------------------------------------------------------------------
[2023-03-18T13:14:51.179+0000] {taskinstance.py:1283} INFO - Starting attempt 29 of 29
[2023-03-18T13:14:51.180+0000] {taskinstance.py:1284} INFO - 
--------------------------------------------------------------------------------
[2023-03-18T13:14:51.198+0000] {taskinstance.py:1303} INFO - Executing <Task(DataprocCreateClusterOperator): create_dataproc_cluster> on 2023-03-18 00:22:20.257510+00:00
[2023-03-18T13:14:51.207+0000] {standard_task_runner.py:55} INFO - Started process 1086 to run task
[2023-03-18T13:14:51.213+0000] {standard_task_runner.py:82} INFO - Running: ['***', 'tasks', 'run', 'transform_bq_data', 'create_dataproc_cluster', 'manual__2023-03-18T00:22:20.257510+00:00', '--job-id', '100', '--raw', '--subdir', 'DAGS_FOLDER/p_spark_processing.py', '--cfg-path', '/tmp/tmp4u_j7w5a']
[2023-03-18T13:14:51.216+0000] {standard_task_runner.py:83} INFO - Job 100: Subtask create_dataproc_cluster
[2023-03-18T13:14:51.237+0000] {warnings.py:110} WARNING - /home/***/.local/lib/python3.7/site-packages/***/settings.py:250: DeprecationWarning: The sql_alchemy_conn option in [core] has been moved to the sql_alchemy_conn option in [database] - the old setting has been used, but please update your config.
  SQL_ALCHEMY_CONN = conf.get("database", "SQL_ALCHEMY_CONN")

[2023-03-18T13:14:51.306+0000] {task_command.py:388} INFO - Running <TaskInstance: transform_bq_data.create_dataproc_cluster manual__2023-03-18T00:22:20.257510+00:00 [running]> on host dd57854ee19e
[2023-03-18T13:14:51.409+0000] {taskinstance.py:1511} INFO - Exporting the following env vars:
AIRFLOW_CTX_DAG_OWNER=***
AIRFLOW_CTX_DAG_ID=transform_bq_data
AIRFLOW_CTX_TASK_ID=create_dataproc_cluster
AIRFLOW_CTX_EXECUTION_DATE=2023-03-18T00:22:20.257510+00:00
AIRFLOW_CTX_TRY_NUMBER=29
AIRFLOW_CTX_DAG_RUN_ID=manual__2023-03-18T00:22:20.257510+00:00
[2023-03-18T13:14:51.411+0000] {dataproc.py:601} INFO - Creating cluster: dataproc-cluster
[2023-03-18T13:14:51.413+0000] {crypto.py:83} WARNING - empty cryptography key - values will not be stored encrypted.
[2023-03-18T13:14:51.413+0000] {base.py:73} INFO - Using connection ID 'google_cloud_default' for task execution.
[2023-03-18T13:14:52.785+0000] {taskinstance.py:1775} ERROR - Task failed with exception
Traceback (most recent call last):
  File "/home/airflow/.local/lib/python3.7/site-packages/google/api_core/grpc_helpers.py", line 50, in error_remapped_callable
    return callable_(*args, **kwargs)
  File "/home/airflow/.local/lib/python3.7/site-packages/grpc/_channel.py", line 946, in __call__
    return _end_unary_response_blocking(state, call, False, None)
  File "/home/airflow/.local/lib/python3.7/site-packages/grpc/_channel.py", line 849, in _end_unary_response_blocking
    raise _InactiveRpcError(state)
grpc._channel._InactiveRpcError: <_InactiveRpcError of RPC that terminated with:
	status = StatusCode.INVALID_ARGUMENT
	details = "User not authorized to act as service account '192108012555-compute@developer.gserviceaccount.com'. To act as a service account, user must have one of [Owner, Editor, Service Account Actor] roles. See https://cloud.google.com/iam/docs/understanding-service-accounts for additional details."
	debug_error_string = "UNKNOWN:Error received from peer ipv4:172.217.168.42:443 {grpc_message:"User not authorized to act as service account \'192108012555-compute@developer.gserviceaccount.com\'. To act as a service account, user must have one of [Owner, Editor, Service Account Actor] roles. See https://cloud.google.com/iam/docs/understanding-service-accounts for additional details.", grpc_status:3, created_time:"2023-03-18T13:14:52.783802034+00:00"}"
>

The above exception was the direct cause of the following exception:

Traceback (most recent call last):
  File "/home/airflow/.local/lib/python3.7/site-packages/airflow/providers/google/cloud/operators/dataproc.py", line 609, in execute
    operation = self._create_cluster(hook)
  File "/home/airflow/.local/lib/python3.7/site-packages/airflow/providers/google/cloud/operators/dataproc.py", line 545, in _create_cluster
    metadata=self.metadata,
  File "/home/airflow/.local/lib/python3.7/site-packages/airflow/providers/google/common/hooks/base_google.py", line 468, in inner_wrapper
    return func(self, *args, **kwargs)
  File "/home/airflow/.local/lib/python3.7/site-packages/airflow/providers/google/cloud/hooks/dataproc.py", line 341, in create_cluster
    metadata=metadata,
  File "/home/airflow/.local/lib/python3.7/site-packages/google/cloud/dataproc_v1/services/cluster_controller/client.py", line 564, in create_cluster
    metadata=metadata,
  File "/home/airflow/.local/lib/python3.7/site-packages/google/api_core/gapic_v1/method.py", line 154, in __call__
    return wrapped_func(*args, **kwargs)
  File "/home/airflow/.local/lib/python3.7/site-packages/google/api_core/retry.py", line 288, in retry_wrapped_func
    on_error=on_error,
  File "/home/airflow/.local/lib/python3.7/site-packages/google/api_core/retry.py", line 190, in retry_target
    return target()
  File "/home/airflow/.local/lib/python3.7/site-packages/google/api_core/timeout.py", line 99, in func_with_timeout
    return func(*args, **kwargs)
  File "/home/airflow/.local/lib/python3.7/site-packages/google/api_core/grpc_helpers.py", line 52, in error_remapped_callable
    raise exceptions.from_grpc_error(exc) from exc
google.api_core.exceptions.InvalidArgument: 400 User not authorized to act as service account '192108012555-compute@developer.gserviceaccount.com'. To act as a service account, user must have one of [Owner, Editor, Service Account Actor] roles. See https://cloud.google.com/iam/docs/understanding-service-accounts for additional details.
[2023-03-18T13:14:52.807+0000] {taskinstance.py:1326} INFO - Marking task as FAILED. dag_id=transform_bq_data, task_id=create_dataproc_cluster, execution_date=20230318T002220, start_date=20230318T131451, end_date=20230318T131452
[2023-03-18T13:14:52.835+0000] {standard_task_runner.py:105} ERROR - Failed to execute job 100 for task create_dataproc_cluster (400 User not authorized to act as service account '192108012555-compute@developer.gserviceaccount.com'. To act as a service account, user must have one of [Owner, Editor, Service Account Actor] roles. See https://cloud.google.com/iam/docs/understanding-service-accounts for additional details.; 1086)
[2023-03-18T13:14:52.874+0000] {local_task_job.py:212} INFO - Task exited with return code 1
[2023-03-18T13:14:52.900+0000] {taskinstance.py:2585} INFO - 0 downstream tasks scheduled from follow-on schedule check
