[2023-03-19T13:41:35.945+0000] {taskinstance.py:1084} INFO - Dependencies all met for dep_context=non-requeueable deps ti=<TaskInstance: transform_bq_data.delete_dataproc_cluster manual__2023-03-19T13:41:19.821677+00:00 [queued]>
[2023-03-19T13:41:35.979+0000] {taskinstance.py:1084} INFO - Dependencies all met for dep_context=requeueable deps ti=<TaskInstance: transform_bq_data.delete_dataproc_cluster manual__2023-03-19T13:41:19.821677+00:00 [queued]>
[2023-03-19T13:41:35.980+0000] {taskinstance.py:1282} INFO - 
--------------------------------------------------------------------------------
[2023-03-19T13:41:35.986+0000] {taskinstance.py:1283} INFO - Starting attempt 1 of 2
[2023-03-19T13:41:35.986+0000] {taskinstance.py:1284} INFO - 
--------------------------------------------------------------------------------
[2023-03-19T13:41:36.056+0000] {taskinstance.py:1303} INFO - Executing <Task(DataprocDeleteClusterOperator): delete_dataproc_cluster> on 2023-03-19 13:41:19.821677+00:00
[2023-03-19T13:41:36.103+0000] {standard_task_runner.py:55} INFO - Started process 3464 to run task
[2023-03-19T13:41:36.175+0000] {standard_task_runner.py:82} INFO - Running: ['***', 'tasks', 'run', 'transform_bq_data', 'delete_dataproc_cluster', 'manual__2023-03-19T13:41:19.821677+00:00', '--job-id', '139', '--raw', '--subdir', 'DAGS_FOLDER/p_spark_processing.py', '--cfg-path', '/tmp/tmpymhswgnz']
[2023-03-19T13:41:36.222+0000] {standard_task_runner.py:83} INFO - Job 139: Subtask delete_dataproc_cluster
[2023-03-19T13:41:36.382+0000] {warnings.py:110} WARNING - /home/***/.local/lib/python3.7/site-packages/***/settings.py:250: DeprecationWarning: The sql_alchemy_conn option in [core] has been moved to the sql_alchemy_conn option in [database] - the old setting has been used, but please update your config.
  SQL_ALCHEMY_CONN = conf.get("database", "SQL_ALCHEMY_CONN")

[2023-03-19T13:41:36.749+0000] {task_command.py:388} INFO - Running <TaskInstance: transform_bq_data.delete_dataproc_cluster manual__2023-03-19T13:41:19.821677+00:00 [running]> on host f1b65b8eb897
[2023-03-19T13:41:37.017+0000] {taskinstance.py:1511} INFO - Exporting the following env vars:
AIRFLOW_CTX_DAG_OWNER=***
AIRFLOW_CTX_DAG_ID=transform_bq_data
AIRFLOW_CTX_TASK_ID=delete_dataproc_cluster
AIRFLOW_CTX_EXECUTION_DATE=2023-03-19T13:41:19.821677+00:00
AIRFLOW_CTX_TRY_NUMBER=1
AIRFLOW_CTX_DAG_RUN_ID=manual__2023-03-19T13:41:19.821677+00:00
[2023-03-19T13:41:37.020+0000] {crypto.py:83} WARNING - empty cryptography key - values will not be stored encrypted.
[2023-03-19T13:41:37.021+0000] {base.py:73} INFO - Using connection ID 'google_cloud_default' for task execution.
[2023-03-19T13:41:37.028+0000] {dataproc.py:901} INFO - Deleting cluster: my-dataproc-cluster
[2023-03-19T13:41:37.365+0000] {taskinstance.py:1775} ERROR - Task failed with exception
Traceback (most recent call last):
  File "/home/airflow/.local/lib/python3.7/site-packages/google/api_core/grpc_helpers.py", line 50, in error_remapped_callable
    return callable_(*args, **kwargs)
  File "/home/airflow/.local/lib/python3.7/site-packages/grpc/_channel.py", line 946, in __call__
    return _end_unary_response_blocking(state, call, False, None)
  File "/home/airflow/.local/lib/python3.7/site-packages/grpc/_channel.py", line 849, in _end_unary_response_blocking
    raise _InactiveRpcError(state)
grpc._channel._InactiveRpcError: <_InactiveRpcError of RPC that terminated with:
	status = StatusCode.NOT_FOUND
	details = "Not found: Cluster projects/dtc-de-course-375420/regions/europe-west6/clusters/my-dataproc-cluster"
	debug_error_string = "UNKNOWN:Error received from peer ipv4:142.250.203.106:443 {grpc_message:"Not found: Cluster projects/dtc-de-course-375420/regions/europe-west6/clusters/my-dataproc-cluster", grpc_status:5, created_time:"2023-03-19T13:41:37.363935772+00:00"}"
>

The above exception was the direct cause of the following exception:

Traceback (most recent call last):
  File "/home/airflow/.local/lib/python3.7/site-packages/airflow/providers/google/cloud/operators/dataproc.py", line 868, in execute
    operation = self._delete_cluster(hook)
  File "/home/airflow/.local/lib/python3.7/site-packages/airflow/providers/google/cloud/operators/dataproc.py", line 910, in _delete_cluster
    metadata=self.metadata,
  File "/home/airflow/.local/lib/python3.7/site-packages/airflow/providers/google/common/hooks/base_google.py", line 468, in inner_wrapper
    return func(self, *args, **kwargs)
  File "/home/airflow/.local/lib/python3.7/site-packages/airflow/providers/google/cloud/hooks/dataproc.py", line 385, in delete_cluster
    metadata=metadata,
  File "/home/airflow/.local/lib/python3.7/site-packages/google/cloud/dataproc_v1/services/cluster_controller/client.py", line 1128, in delete_cluster
    metadata=metadata,
  File "/home/airflow/.local/lib/python3.7/site-packages/google/api_core/gapic_v1/method.py", line 154, in __call__
    return wrapped_func(*args, **kwargs)
  File "/home/airflow/.local/lib/python3.7/site-packages/google/api_core/retry.py", line 288, in retry_wrapped_func
    on_error=on_error,
  File "/home/airflow/.local/lib/python3.7/site-packages/google/api_core/retry.py", line 190, in retry_target
    return target()
  File "/home/airflow/.local/lib/python3.7/site-packages/google/api_core/timeout.py", line 99, in func_with_timeout
    return func(*args, **kwargs)
  File "/home/airflow/.local/lib/python3.7/site-packages/google/api_core/grpc_helpers.py", line 52, in error_remapped_callable
    raise exceptions.from_grpc_error(exc) from exc
google.api_core.exceptions.NotFound: 404 Not found: Cluster projects/dtc-de-course-375420/regions/europe-west6/clusters/my-dataproc-cluster
[2023-03-19T13:41:37.433+0000] {taskinstance.py:1326} INFO - Marking task as UP_FOR_RETRY. dag_id=transform_bq_data, task_id=delete_dataproc_cluster, execution_date=20230319T134119, start_date=20230319T134135, end_date=20230319T134137
[2023-03-19T13:41:37.490+0000] {standard_task_runner.py:105} ERROR - Failed to execute job 139 for task delete_dataproc_cluster (404 Not found: Cluster projects/dtc-de-course-375420/regions/europe-west6/clusters/my-dataproc-cluster; 3464)
[2023-03-19T13:41:37.543+0000] {local_task_job.py:212} INFO - Task exited with return code 1
[2023-03-19T13:41:37.580+0000] {taskinstance.py:2585} INFO - 0 downstream tasks scheduled from follow-on schedule check
